Workbook

Sheet Coin half cell-data
A1: Name/ID | B1: channel ID | C1: Sample Name | D1: Recipe | E1: Total electrode weight (mg) | F1: Electrode Thickness(µm) | G1: Electrode Diameter(mm) | H1: Coating weight (mg) | I1: Active mass (mg) | J1: Loading level(mg/cm^2) | K1: Electrode Density ( g/cm^3) | L1: Porosity | M1: Iterations
A2: 11573 | B2: 51_05_08 | C2: UKP241003 | D2: Production | E2: 24 | G2: 12.7 | H2: =Table1[[#This Row],[Total electrode weight (mg)]] - IF(ROW()<40, Constants!$B$2 * PI()*(Table1[[#This Row],[Electrode Diameter(mm)]]/(10*2))^2, Constants!$B$4 * PI()*(Table1[[#This Row],[Electrode Diameter(mm)]]/(10*2))^2) -> 18.882254 | I2: =IF(D2="", "", IF(D2="RnD", H2*0.85, IF(D2="Production", H2*0.93, "Invalid"))) -> 17.560497 | J2: =Table1[[#This Row],[Coating weight (mg)]]/Constants!$C$2 -> 14.905842 | K2: =(Table1[[#This Row],[Coating weight (mg)]]/1000)/(((Table1[[#This Row],[Electrode Thickness(µm)]]-Constants!$E$4)*10^-4)*Constants!$C$4) -> -12.421535
A3: 11574 | B3: 51_06_02 | C3: UKP241003 | D3: Production | E3: 23.2 | G3: 12.7 | H3: =Table1[[#This Row],[Total electrode weight (mg)]] - IF(ROW()<40, Constants!$B$2 * PI()*(Table1[[#This Row],[Electrode Diameter(mm)]]/(10*2))^2, Constants!$B$4 * PI()*(Table1[[#This Row],[Electrode Diameter(mm)]]/(10*2))^2) -> 18.082254 | I3: =IF(D3="", "", IF(D3="RnD", H3*0.85, IF(D3="Production", H3*0.93, "Invalid"))) -> 16.816497 | J3: =Table1[[#This Row],[Coating weight (mg)]]/Constants!$C$2 -> 14.274314 | K3: =(Table1[[#This Row],[Coating weight (mg)]]/1000)/(((Table1[[#This Row],[Electrode Thickness(µm)]]-Constants!$E$4)*10^-4)*Constants!$C$4) -> -11.895262
A4: 11575 | B4: 51_06_05 | C4: UKP241003 | D4: Production | E4: 22.8 | G4: 12.7 | H4: =Table1[[#This Row],[Total electrode weight (mg)]] - IF(ROW()<40, Constants!$B$2 * PI()*(Table1[[#This Row],[Electrode Diameter(mm)]]/(10*2))^2, Constants!$B$4 * PI()*(Table1[[#This Row],[Electrode Diameter(mm)]]/(10*2))^2) -> 17.682254 | I4: =IF(D4="", "", IF(D4="RnD", H4*0.85, IF(D4="Production", H4*0.93, "Invalid"))) -> 16.444497 | J4: =Table1[[#This Row],[Coating weight (mg)]]/Constants!$C$2 -> 13.95855 | K4: =(Table1[[#This Row],[Coating weight (mg)]]/1000)/(((Table1[[#This Row],[Electrode Thickness(µm)]]-Constants!$E$4)*10^-4)*Constants!$C$4) -> -11.632125
A5: 11614 | B5: 51_08_01 | C5: UKP241003 | D5: Production | E5: 25.4 | G5: 12.7 | H5: =Table1[[#This Row],[Total electrode weight (mg)]] - IF(ROW()<40, Constants!$B$2 * PI()*(Table1[[#This Row],[Electrode Diameter(mm)]]/(10*2))^2, Constants!$B$4 * PI()*(Table1[[#This Row],[Electrode Diameter(mm)]]/(10*2))^2) -> 20.282254 | I5: =IF(D5="", "", IF(D5="RnD", H5*0.85, IF(D5="Production", H5*0.93, "Invalid"))) -> 18.862497 | J5: =Table1[[#This Row],[Coating weight (mg)]]/Constants!$C$2 -> 16.011016 | K5: =(Table1[[#This Row],[Coating weight (mg)]]/1000)/(((Table1[[#This Row],[Electrode Thickness(µm)]]-Constants!$E$4)*10^-4)*Constants!$C$4) -> -13.342514
A6: 11615 | C6: UKP241003 | D6: Production | E6: 24.2 | G6: 12.7 | H6: =Table1[[#This Row],[Total electrode weight (mg)]] - IF(ROW()<40, Constants!$B$2 * PI()*(Table1[[#This Row],[Electrode Diameter(mm)]]/(10*2))^2, Constants!$B$4 * PI()*(Table1[[#This Row],[Electrode Diameter(mm)]]/(10*2))^2) -> 19.082254 | I6: =IF(D6="", "", IF(D6="RnD", H6*0.85, IF(D6="Production", H6*0.93, "Invalid"))) -> 17.746497 | J6: =Table1[[#This Row],[Coating weight (mg)]]/Constants!$C$2 -> 15.063724 | K6: =(Table1[[#This Row],[Coating weight (mg)]]/1000)/(((Table1[[#This Row],[Electrode Thickness(µm)]]-Constants!$E$4)*10^-4)*Constants!$C$4) -> -12.553104
A7: 11616 | C7: UKP241003 | D7: Production | E7: 24.5 | G7: 12.7 | H7: =Table1[[#This Row],[Total electrode weight (mg)]] - IF(ROW()<40, Constants!$B$2 * PI()*(Table1[[#This Row],[Electrode Diameter(mm)]]/(10*2))^2, Constants!$B$4 * PI()*(Table1[[#This Row],[Electrode Diameter(mm)]]/(10*2))^2) -> 19.382254 | I7: =IF(D7="", "", IF(D7="RnD", H7*0.85, IF(D7="Production", H7*0.93, "Invalid"))) -> 18.025497 | J7: =Table1[[#This Row],[Coating weight (mg)]]/Constants!$C$2 -> 15.300547 | K7: =(Table1[[#This Row],[Coating weight (mg)]]/1000)/(((Table1[[#This Row],[Electrode Thickness(µm)]]-Constants!$E$4)*10^-4)*Constants!$C$4) -> -12.750456
A8: 11617 | C8: UKP241003 | D8: Production | E8: 23.6 | G8: 12.7 | H8: =Table1[[#This Row],[Total electrode weight (mg)]] - IF(ROW()<40, Constants!$B$2 * PI()*(Table1[[#This Row],[Electrode Diameter(mm)]]/(10*2))^2, Constants!$B$4 * PI()*(Table1[[#This Row],[Electrode Diameter(mm)]]/(10*2))^2) -> 18.482254 | I8: =IF(D8="", "", IF(D8="RnD", H8*0.85, IF(D8="Production", H8*0.93, "Invalid"))) -> 17.188497 | J8: =Table1[[#This Row],[Coating weight (mg)]]/Constants!$C$2 -> 14.590078 | K8: =(Table1[[#This Row],[Coating weight (mg)]]/1000)/(((Table1[[#This Row],[Electrode Thickness(µm)]]-Constants!$E$4)*10^-4)*Constants!$C$4) -> -12.158399
A9: 11621 | B9: 51_05_01 | C9: CQA-1002 | D9: Production | E9: 24.4 | G9: 12.7 | H9: =Table1[[#This Row],[Total electrode weight (mg)]] - IF(ROW()<40, Constants!$B$2 * PI()*(Table1[[#This Row],[Electrode Diameter(mm)]]/(10*2))^2, Constants!$B$4 * PI()*(Table1[[#This Row],[Electrode Diameter(mm)]]/(10*2))^2) -> 19.282254 | I9: =IF(D9="", "", IF(D9="RnD", H9*0.85, IF(D9="Production", H9*0.93, "Invalid"))) -> 17.932497 | J9: =Table1[[#This Row],[Coating weight (mg)]]/Constants!$C$2 -> 15.221606 | K9: =(Table1[[#This Row],[Coating weight (mg)]]/1000)/(((Table1[[#This Row],[Electrode Thickness(µm)]]-Constants!$E$4)*10^-4)*Constants!$C$4) -> -12.684672
A10: 11622 | B10: 51_05_06 | C10: CQA-1002 | D10: Production | E10: 23.6 | G10: 12.7 | H10: =Table1[[#This Row],[Total electrode weight (mg)]] - IF(ROW()<40, Constants!$B$2 * PI()*(Table1[[#This Row],[Electrode Diameter(mm)]]/(10*2))^2, Constants!$B$4 * PI()*(Table1[[#This Row],[Electrode Diameter(mm)]]/(10*2))^2) -> 18.482254 | I10: =IF(D10="", "", IF(D10="RnD", H10*0.85, IF(D10="Production", H10*0.93, "Invalid"))) -> 17.188497 | J10: =Table1[[#This Row],[Coating weight (mg)]]/Constants!$C$2 -> 14.590078 | K10: =(Table1[[#This Row],[Coating weight (mg)]]/1000)/(((Table1[[#This Row],[Electrode Thickness(µm)]]-Constants!$E$4)*10^-4)*Constants!$C$4) -> -12.158399
A11: 11623 | B11: 51_05_07 | C11: CQA-1002 | D11: Production | E11: 23.9 | G11: 12.7 | H11: =Table1[[#This Row],[Total electrode weight (mg)]] - IF(ROW()<40, Constants!$B$2 * PI()*(Table1[[#This Row],[Electrode Diameter(mm)]]/(10*2))^2, Constants!$B$4 * PI()*(Table1[[#This Row],[Electrode Diameter(mm)]]/(10*2))^2) -> 18.782254 | I11: =IF(D11="", "", IF(D11="RnD", H11*0.85, IF(D11="Production", H11*0.93, "Invalid"))) -> 17.467497 | J11: =Table1[[#This Row],[Coating weight (mg)]]/Constants!$C$2 -> 14.826901 | K11: =(Table1[[#This Row],[Coating weight (mg)]]/1000)/(((Table1[[#This Row],[Electrode Thickness(µm)]]-Constants!$E$4)*10^-4)*Constants!$C$4) -> -12.355751
A12: 11624 | B12: 51_02_07 | C12: CQA-1002 | D12: Production | E12: 23.3 | G12: 12.7 | H12: =Table1[[#This Row],[Total electrode weight (mg)]] - IF(ROW()<40, Constants!$B$2 * PI()*(Table1[[#This Row],[Electrode Diameter(mm)]]/(10*2))^2, Constants!$B$4 * PI()*(Table1[[#This Row],[Electrode Diameter(mm)]]/(10*2))^2) -> 18.182254 | I12: =IF(D12="", "", IF(D12="RnD", H12*0.85, IF(D12="Production", H12*0.93, "Invalid"))) -> 16.909497 | J12: =Table1[[#This Row],[Coating weight (mg)]]/Constants!$C$2 -> 14.353255 | K12: =(Table1[[#This Row],[Coating weight (mg)]]/1000)/(((Table1[[#This Row],[Electrode Thickness(µm)]]-Constants!$E$4)*10^-4)*Constants!$C$4) -> -11.961046
A13: 11625 | B13: 51_03_03 | C13: CQA-1002 | D13: Production | E13: 24.2 | G13: 12.7 | H13: =Table1[[#This Row],[Total electrode weight (mg)]] - IF(ROW()<40, Constants!$B$2 * PI()*(Table1[[#This Row],[Electrode Diameter(mm)]]/(10*2))^2, Constants!$B$4 * PI()*(Table1[[#This Row],[Electrode Diameter(mm)]]/(10*2))^2) -> 19.082254 | I13: =IF(D13="", "", IF(D13="RnD", H13*0.85, IF(D13="Production", H13*0.93, "Invalid"))) -> 17.746497 | J13: =Table1[[#This Row],[Coating weight (mg)]]/Constants!$C$2 -> 15.063724 | K13: =(Table1[[#This Row],[Coating weight (mg)]]/1000)/(((Table1[[#This Row],[Electrode Thickness(µm)]]-Constants!$E$4)*10^-4)*Constants!$C$4) -> -12.553104
A14: 11644 | B14: 51_08_01 | C14: CQA-1030 | D14: Production | E14: 24.1 | G14: 12.7 | H14: =Table1[[#This Row],[Total electrode weight (mg)]] - IF(ROW()<40, Constants!$B$2 * PI()*(Table1[[#This Row],[Electrode Diameter(mm)]]/(10*2))^2, Constants!$B$4 * PI()*(Table1[[#This Row],[Electrode Diameter(mm)]]/(10*2))^2) -> 18.982254 | I14: =IF(D14="", "", IF(D14="RnD", H14*0.85, IF(D14="Production", H14*0.93, "Invalid"))) -> 17.653497 | J14: =Table1[[#This Row],[Coating weight (mg)]]/Constants!$C$2 -> 14.984783 | K14: =(Table1[[#This Row],[Coating weight (mg)]]/1000)/(((Table1[[#This Row],[Electrode Thickness(µm)]]-Constants!$E$4)*10^-4)*Constants!$C$4) -> -12.487319
A15: 11645 | B15: 51_08_02 | C15: CQA-1030 | D15: Production | E15: 23.6 | G15: 12.7 | H15: =Table1[[#This Row],[Total electrode weight (mg)]] - IF(ROW()<40, Constants!$B$2 * PI()*(Table1[[#This Row],[Electrode Diameter(mm)]]/(10*2))^2, Constants!$B$4 * PI()*(Table1[[#This Row],[Electrode Diameter(mm)]]/(10*2))^2) -> 18.482254 | I15: =IF(D15="", "", IF(D15="RnD", H15*0.85, IF(D15="Production", H15*0.93, "Invalid"))) -> 17.188497 | J15: =Table1[[#This Row],[Coating weight (mg)]]/Constants!$C$2 -> 14.590078 | K15: =(Table1[[#This Row],[Coating weight (mg)]]/1000)/(((Table1[[#This Row],[Electrode Thickness(µm)]]-Constants!$E$4)*10^-4)*Constants!$C$4) -> -12.158399
A16: 11646 | B16: 51_08_03 | C16: CQA-1030 | D16: Production | E16: 23.3 | G16: 12.7 | H16: =Table1[[#This Row],[Total electrode weight (mg)]] - IF(ROW()<40, Constants!$B$2 * PI()*(Table1[[#This Row],[Electrode Diameter(mm)]]/(10*2))^2, Constants!$B$4 * PI()*(Table1[[#This Row],[Electrode Diameter(mm)]]/(10*2))^2) -> 18.182254 | I16: =IF(D16="", "", IF(D16="RnD", H16*0.85, IF(D16="Production", H16*0.93, "Invalid"))) -> 16.909497 | J16: =Table1[[#This Row],[Coating weight (mg)]]/Constants!$C$2 -> 14.353255 | K16: =(Table1[[#This Row],[Coating weight (mg)]]/1000)/(((Table1[[#This Row],[Electrode Thickness(µm)]]-Constants!$E$4)*10^-4)*Constants!$C$4) -> -11.961046
A17: 11647 | B17: 51_08_04 | C17: CQA-1030 | D17: Production | E17: 24 | G17: 12.7 | H17: =Table1[[#This Row],[Total electrode weight (mg)]] - IF(ROW()<40, Constants!$B$2 * PI()*(Table1[[#This Row],[Electrode Diameter(mm)]]/(10*2))^2, Constants!$B$4 * PI()*(Table1[[#This Row],[Electrode Diameter(mm)]]/(10*2))^2) -> 18.882254 | I17: =IF(D17="", "", IF(D17="RnD", H17*0.85, IF(D17="Production", H17*0.93, "Invalid"))) -> 17.560497 | J17: =Table1[[#This Row],[Coating weight (mg)]]/Constants!$C$2 -> 14.905842 | K17: =(Table1[[#This Row],[Coating weight (mg)]]/1000)/(((Table1[[#This Row],[Electrode Thickness(µm)]]-Constants!$E$4)*10^-4)*Constants!$C$4) -> -12.421535
A18: 11668 | B18: 51_02_07 | C18: CQA-1003 | D18: Production | E18: 41.1 | G18: 12.7 | H18: =Table1[[#This Row],[Total electrode weight (mg)]] - IF(ROW()<40, Constants!$B$2 * PI()*(Table1[[#This Row],[Electrode Diameter(mm)]]/(10*2))^2, Constants!$B$4 * PI()*(Table1[[#This Row],[Electrode Diameter(mm)]]/(10*2))^2) -> 35.982254 | I18: =IF(D18="", "", IF(D18="RnD", H18*0.85, IF(D18="Production", H18*0.93, "Invalid"))) -> 33.463497 | J18: =Table1[[#This Row],[Coating weight (mg)]]/Constants!$C$2 -> 28.404755 | K18: =(Table1[[#This Row],[Coating weight (mg)]]/1000)/(((Table1[[#This Row],[Electrode Thickness(µm)]]-Constants!$E$4)*10^-4)*Constants!$C$4) -> -23.670629
A19: 11669 | B19: 51_05_01 | C19: CQA-1003 | D19: Production | E19: 43.7 | G19: 12.7 | H19: =Table1[[#This Row],[Total electrode weight (mg)]] - IF(ROW()<40, Constants!$B$2 * PI()*(Table1[[#This Row],[Electrode Diameter(mm)]]/(10*2))^2, Constants!$B$4 * PI()*(Table1[[#This Row],[Electrode Diameter(mm)]]/(10*2))^2) -> 38.582254 | I19: =IF(D19="", "", IF(D19="RnD", H19*0.85, IF(D19="Production", H19*0.93, "Invalid"))) -> 35.881497 | J19: =Table1[[#This Row],[Coating weight (mg)]]/Constants!$C$2 -> 30.457221 | K19: =(Table1[[#This Row],[Coating weight (mg)]]/1000)/(((Table1[[#This Row],[Electrode Thickness(µm)]]-Constants!$E$4)*10^-4)*Constants!$C$4) -> -25.381018
A20: 11670 | B20: 51_10_07 | C20: CQA-1003 | D20: Production | E20: 42.3 | G20: 12.7 | H20: =Table1[[#This Row],[Total electrode weight (mg)]] - IF(ROW()<40, Constants!$B$2 * PI()*(Table1[[#This Row],[Electrode Diameter(mm)]]/(10*2))^2, Constants!$B$4 * PI()*(Table1[[#This Row],[Electrode Diameter(mm)]]/(10*2))^2) -> 37.182254 | I20: =IF(D20="", "", IF(D20="RnD", H20*0.85, IF(D20="Production", H20*0.93, "Invalid"))) -> 34.579497 | J20: =Table1[[#This Row],[Coating weight (mg)]]/Constants!$C$2 -> 29.352047 | K20: =(Table1[[#This Row],[Coating weight (mg)]]/1000)/(((Table1[[#This Row],[Electrode Thickness(µm)]]-Constants!$E$4)*10^-4)*Constants!$C$4) -> -24.460039
... A37: 11687 | B37: 51_07_06 | C37: UKP250101 | D37: Production | E37: 22.5 | G37: 12.7 | H37: =Table1[[#This Row],[Total electrode weight (mg)]] - IF(ROW()<40, Constants!$B$2 * PI()*(Table1[[#This Row],[Electrode Diameter(mm)]]/(10*2))^2, Constants!$B$4 * PI()*(Table1[[#This Row],[Electrode Diameter(mm)]]/(10*2))^2) -> 17.382254 | I37: =IF(D37="", "", IF(D37="RnD", H37*0.85, IF(D37="Production", H37*0.93, "Invalid"))) -> 16.165497 | J37: =Table1[[#This Row],[Coating weight (mg)]]/Constants!$C$2 -> 13.721727 | K37: =(Table1[[#This Row],[Coating weight (mg)]]/1000)/(((Table1[[#This Row],[Electrode Thickness(µm)]]-Constants!$E$4)*10^-4)*Constants!$C$4) -> -11.434773
A38: 11692 | B38: 51_08_01 | C38: CQA-1026 | E38: 10 | G38: 12.7 | H38: =Table1[[#This Row],[Total electrode weight (mg)]] - IF(ROW()<40, Constants!$B$2 * PI()*(Table1[[#This Row],[Electrode Diameter(mm)]]/(10*2))^2, Constants!$B$4 * PI()*(Table1[[#This Row],[Electrode Diameter(mm)]]/(10*2))^2) -> 4.8822545 | I38: =IF(D38="", "", IF(D38="RnD", H38*0.85, IF(D38="Production", H38*0.93, "Invalid"))) | J38: =Table1[[#This Row],[Coating weight (mg)]]/Constants!$C$2 -> 3.854101 | K38: =(Table1[[#This Row],[Coating weight (mg)]]/1000)/(((Table1[[#This Row],[Electrode Thickness(µm)]]-Constants!$E$4)*10^-4)*Constants!$C$4) -> -3.2117508
A39: 11693 | B39: 51_08_04 | E39: 24.2 | G39: 12.7 | H39: =Table1[[#This Row],[Total electrode weight (mg)]] - IF(ROW()<40, Constants!$B$2 * PI()*(Table1[[#This Row],[Electrode Diameter(mm)]]/(10*2))^2, Constants!$B$4 * PI()*(Table1[[#This Row],[Electrode Diameter(mm)]]/(10*2))^2) -> 19.082254 | I39: =IF(D39="", "", IF(D39="RnD", H39*0.85, IF(D39="Production", H39*0.93, "Invalid"))) | J39: =Table1[[#This Row],[Coating weight (mg)]]/Constants!$C$2 -> 15.063724 | K39: =(Table1[[#This Row],[Coating weight (mg)]]/1000)/(((Table1[[#This Row],[Electrode Thickness(µm)]]-Constants!$E$4)*10^-4)*Constants!$C$4) -> -12.553104
A40: 11697 | B40: 51_04_02 | C40: UKP250201 | D40: Production | E40: 20.7 | G40: 12.7 | H40: =Table1[[#This Row],[Total electrode weight (mg)]] - IF(ROW()<40, Constants!$B$2 * PI()*(Table1[[#This Row],[Electrode Diameter(mm)]]/(10*2))^2, Constants!$B$4 * PI()*(Table1[[#This Row],[Electrode Diameter(mm)]]/(10*2))^2) -> 16.645073 | I40: =IF(D40="", "", IF(D40="RnD", H40*0.85, IF(D40="Production", H40*0.93, "Invalid"))) -> 15.479918 | J40: =Table1[[#This Row],[Coating weight (mg)]]/Constants!$C$2 -> 13.139789 | K40: =(Table1[[#This Row],[Coating weight (mg)]]/1000)/(((Table1[[#This Row],[Electrode Thickness(µm)]]-Constants!$E$4)*10^-4)*Constants!$C$4) -> -10.949824
A41: 11698 | B41: 51_05_04 | C41: UKP250201 | D41: Production | E41: 20.7 | G41: 12.7 | H41: =Table1[[#This Row],[Total electrode weight (mg)]] - IF(ROW()<40, Constants!$B$2 * PI()*(Table1[[#This Row],[Electrode Diameter(mm)]]/(10*2))^2, Constants!$B$4 * PI()*(Table1[[#This Row],[Electrode Diameter(mm)]]/(10*2))^2) -> 16.645073 | I41: =IF(D41="", "", IF(D41="RnD", H41*0.85, IF(D41="Production", H41*0.93, "Invalid"))) -> 15.479918 | J41: =Table1[[#This Row],[Coating weight (mg)]]/Constants!$C$2 -> 13.139789 | K41: =(Table1[[#This Row],[Coating weight (mg)]]/1000)/(((Table1[[#This Row],[Electrode Thickness(µm)]]-Constants!$E$4)*10^-4)*Constants!$C$4) -> -10.949824
A42: 11699 | B42: 51_06_08 | C42: UKP250201 | D42: Production | E42: 20.9 | G42: 12.7 | H42: =Table1[[#This Row],[Total electrode weight (mg)]] - IF(ROW()<40, Constants!$B$2 * PI()*(Table1[[#This Row],[Electrode Diameter(mm)]]/(10*2))^2, Constants!$B$4 * PI()*(Table1[[#This Row],[Electrode Diameter(mm)]]/(10*2))^2) -> 16.845073 | I42: =IF(D42="", "", IF(D42="RnD", H42*0.85, IF(D42="Production", H42*0.93, "Invalid"))) -> 15.665918 | J42: =Table1[[#This Row],[Coating weight (mg)]]/Constants!$C$2 -> 13.297671 | K42: =(Table1[[#This Row],[Coating weight (mg)]]/1000)/(((Table1[[#This Row],[Electrode Thickness(µm)]]-Constants!$E$4)*10^-4)*Constants!$C$4) -> -11.081393
A43: 11700 | B43: 51_09_03 | C43: UKP250201 | D43: Production | E43: 20.6 | G43: 12.7 | H43: =Table1[[#This Row],[Total electrode weight (mg)]] - IF(ROW()<40, Constants!$B$2 * PI()*(Table1[[#This Row],[Electrode Diameter(mm)]]/(10*2))^2, Constants!$B$4 * PI()*(Table1[[#This Row],[Electrode Diameter(mm)]]/(10*2))^2) -> 16.545073 | I43: =IF(D43="", "", IF(D43="RnD", H43*0.85, IF(D43="Production", H43*0.93, "Invalid"))) -> 15.386918 | J43: =Table1[[#This Row],[Coating weight (mg)]]/Constants!$C$2 -> 13.060848 | K43: =(Table1[[#This Row],[Coating weight (mg)]]/1000)/(((Table1[[#This Row],[Electrode Thickness(µm)]]-Constants!$E$4)*10^-4)*Constants!$C$4) -> -10.88404
A44: 11701 | B44: 51_07_01 | C44: UKP250201 | D44: Production | E44: 19.8 | G44: 12.7 | H44: =Table1[[#This Row],[Total electrode weight (mg)]] - IF(ROW()<40, Constants!$B$2 * PI()*(Table1[[#This Row],[Electrode Diameter(mm)]]/(10*2))^2, Constants!$B$4 * PI()*(Table1[[#This Row],[Electrode Diameter(mm)]]/(10*2))^2) -> 15.745073 | I44: =IF(D44="", "", IF(D44="RnD", H44*0.85, IF(D44="Production", H44*0.93, "Invalid"))) -> 14.642918 | J44: =Table1[[#This Row],[Coating weight (mg)]]/Constants!$C$2 -> 12.42932 | K44: =(Table1[[#This Row],[Coating weight (mg)]]/1000)/(((Table1[[#This Row],[Electrode Thickness(µm)]]-Constants!$E$4)*10^-4)*Constants!$C$4) -> -10.357767
A45: 11702 | B45: 51_07_02 | C45: UKP250201 | D45: Production | E45: 22 | G45: 12.7 | H45: =Table1[[#This Row],[Total electrode weight (mg)]] - IF(ROW()<40, Constants!$B$2 * PI()*(Table1[[#This Row],[Electrode Diameter(mm)]]/(10*2))^2, Constants!$B$4 * PI()*(Table1[[#This Row],[Electrode Diameter(mm)]]/(10*2))^2) -> 17.945073 | I45: =IF(D45="", "", IF(D45="RnD", H45*0.85, IF(D45="Production", H45*0.93, "Invalid"))) -> 16.688918 | J45: =Table1[[#This Row],[Coating weight (mg)]]/Constants!$C$2 -> 14.166022 | K45: =(Table1[[#This Row],[Coating weight (mg)]]/1000)/(((Table1[[#This Row],[Electrode Thickness(µm)]]-Constants!$E$4)*10^-4)*Constants!$C$4) -> -11.805018
A46: 11703 | B46: 51_07-03 | C46: UKP250201 | D46: Production | E46: 21.9 | G46: 12.7 | H46: =Table1[[#This Row],[Total electrode weight (mg)]] - IF(ROW()<40, Constants!$B$2 * PI()*(Table1[[#This Row],[Electrode Diameter(mm)]]/(10*2))^2, Constants!$B$4 * PI()*(Table1[[#This Row],[Electrode Diameter(mm)]]/(10*2))^2) -> 17.845073 | I46: =IF(D46="", "", IF(D46="RnD", H46*0.85, IF(D46="Production", H46*0.93, "Invalid"))) -> 16.595918 | J46: =Table1[[#This Row],[Coating weight (mg)]]/Constants!$C$2 -> 14.087081 | K46: =(Table1[[#This Row],[Coating weight (mg)]]/1000)/(((Table1[[#This Row],[Electrode Thickness(µm)]]-Constants!$E$4)*10^-4)*Constants!$C$4) -> -11.739234
A47: 11707 | B47: 51_07-04 | C47: QD-600L-241204 | D47: Production | E47: 21 | G47: 12.7 | H47: =Table1[[#This Row],[Total electrode weight (mg)]] - IF(ROW()<40, Constants!$B$2 * PI()*(Table1[[#This Row],[Electrode Diameter(mm)]]/(10*2))^2, Constants!$B$4 * PI()*(Table1[[#This Row],[Electrode Diameter(mm)]]/(10*2))^2) -> 16.945073 | I47: =IF(D47="", "", IF(D47="RnD", H47*0.85, IF(D47="Production", H47*0.93, "Invalid"))) -> 15.758918 | J47: =Table1[[#This Row],[Coating weight (mg)]]/Constants!$C$2 -> 13.376612 | K47: =(Table1[[#This Row],[Coating weight (mg)]]/1000)/(((Table1[[#This Row],[Electrode Thickness(µm)]]-Constants!$E$4)*10^-4)*Constants!$C$4) -> -11.147177
A48: 11708 | B48: 51_07-05 | C48: QD-600L-241204 | D48: Production | E48: 22.7 | G48: 12.7 | H48: =Table1[[#This Row],[Total electrode weight (mg)]] - IF(ROW()<40, Constants!$B$2 * PI()*(Table1[[#This Row],[Electrode Diameter(mm)]]/(10*2))^2, Constants!$B$4 * PI()*(Table1[[#This Row],[Electrode Diameter(mm)]]/(10*2))^2) -> 18.645073 | I48: =IF(D48="", "", IF(D48="RnD", H48*0.85, IF(D48="Production", H48*0.93, "Invalid"))) -> 17.339918 | J48: =Table1[[#This Row],[Coating weight (mg)]]/Constants!$C$2 -> 14.718609 | K48: =(Table1[[#This Row],[Coating weight (mg)]]/1000)/(((Table1[[#This Row],[Electrode Thickness(µm)]]-Constants!$E$4)*10^-4)*Constants!$C$4) -> -12.265508
A49: 11709 | B49: 51_07-06 | C49: QD-600L-241204 | D49: Production | E49: 21.9 | G49: 12.7 | H49: =Table1[[#This Row],[Total electrode weight (mg)]] - IF(ROW()<40, Constants!$B$2 * PI()*(Table1[[#This Row],[Electrode Diameter(mm)]]/(10*2))^2, Constants!$B$4 * PI()*(Table1[[#This Row],[Electrode Diameter(mm)]]/(10*2))^2) -> 17.845073 | I49: =IF(D49="", "", IF(D49="RnD", H49*0.85, IF(D49="Production", H49*0.93, "Invalid"))) -> 16.595918 | J49: =Table1[[#This Row],[Coating weight (mg)]]/Constants!$C$2 -> 14.087081 | K49: =(Table1[[#This Row],[Coating weight (mg)]]/1000)/(((Table1[[#This Row],[Electrode Thickness(µm)]]-Constants!$E$4)*10^-4)*Constants!$C$4) -> -11.739234
A50: 11710 | B50: 51_07-07 | C50: QD-600L-241204 | D50: Production | E50: 21.3 | G50: 12.7 | H50: =Table1[[#This Row],[Total electrode weight (mg)]] - IF(ROW()<40, Constants!$B$2 * PI()*(Table1[[#This Row],[Electrode Diameter(mm)]]/(10*2))^2, Constants!$B$4 * PI()*(Table1[[#This Row],[Electrode Diameter(mm)]]/(10*2))^2) -> 17.245073 | I50: =IF(D50="", "", IF(D50="RnD", H50*0.85, IF(D50="Production", H50*0.93, "Invalid"))) -> 16.037918 | J50: =Table1[[#This Row],[Coating weight (mg)]]/Constants!$C$2 -> 13.613435 | K50: =(Table1[[#This Row],[Coating weight (mg)]]/1000)/(((Table1[[#This Row],[Electrode Thickness(µm)]]-Constants!$E$4)*10^-4)*Constants!$C$4) -> -11.344529
A51: 11714 | B51: 51_07_01 | C51: UKP250202 | D51: Production | E51: 21.1 | G51: 12.7 | H51: =Table1[[#This Row],[Total electrode weight (mg)]] - IF(ROW()<40, Constants!$B$2 * PI()*(Table1[[#This Row],[Electrode Diameter(mm)]]/(10*2))^2, Constants!$B$4 * PI()*(Table1[[#This Row],[Electrode Diameter(mm)]]/(10*2))^2) -> 17.045073 | I51: =IF(D51="", "", IF(D51="RnD", H51*0.85, IF(D51="Production", H51*0.93, "Invalid"))) -> 15.851918 | J51: =Table1[[#This Row],[Coating weight (mg)]]/Constants!$C$2 -> 13.455553 | K51: =(Table1[[#This Row],[Coating weight (mg)]]/1000)/(((Table1[[#This Row],[Electrode Thickness(µm)]]-Constants!$E$4)*10^-4)*Constants!$C$4) -> -11.212961
... A87: 11820 | B87: 20_04_01 | C87: FPP-02-Mn-I | D87: RnD | E87: 21 | G87: 12.7 | H87: =Table1[[#This Row],[Total electrode weight (mg)]] - IF(ROW()<40, Constants!$B$2 * PI()*(Table1[[#This Row],[Electrode Diameter(mm)]]/(10*2))^2, Constants!$B$4 * PI()*(Table1[[#This Row],[Electrode Diameter(mm)]]/(10*2))^2) -> 16.945073 | I87: =IF(D87="", "", IF(D87="RnD", H87*0.85, IF(D87="Production", H87*0.93, "Invalid"))) -> 14.403312 | J87: =Table1[[#This Row],[Coating weight (mg)]]/Constants!$C$2 -> 13.376612 | K87: =(Table1[[#This Row],[Coating weight (mg)]]/1000)/(((Table1[[#This Row],[Electrode Thickness(µm)]]-Constants!$E$4)*10^-4)*Constants!$C$4) -> -11.147177
A88: 11821 | C88: FPP-02-Mn-I | D88: RnD | E88: 20.1 | G88: 12.7 | H88: =Table1[[#This Row],[Total electrode weight (mg)]] - IF(ROW()<40, Constants!$B$2 * PI()*(Table1[[#This Row],[Electrode Diameter(mm)]]/(10*2))^2, Constants!$B$4 * PI()*(Table1[[#This Row],[Electrode Diameter(mm)]]/(10*2))^2) -> 16.045073 | I88: =IF(D88="", "", IF(D88="RnD", H88*0.85, IF(D88="Production", H88*0.93, "Invalid"))) -> 13.638312 | J88: =Table1[[#This Row],[Coating weight (mg)]]/Constants!$C$2 -> 12.666143 | K88: =(Table1[[#This Row],[Coating weight (mg)]]/1000)/(((Table1[[#This Row],[Electrode Thickness(µm)]]-Constants!$E$4)*10^-4)*Constants!$C$4) -> -10.555119
A89: 11822 | B89: 20_04_03 | C89: FPP-02-Mn-I | D89: RnD | E89: 19.2 | G89: 12.7 | H89: =Table1[[#This Row],[Total electrode weight (mg)]] - IF(ROW()<40, Constants!$B$2 * PI()*(Table1[[#This Row],[Electrode Diameter(mm)]]/(10*2))^2, Constants!$B$4 * PI()*(Table1[[#This Row],[Electrode Diameter(mm)]]/(10*2))^2) -> 15.145073 | I89: =IF(D89="", "", IF(D89="RnD", H89*0.85, IF(D89="Production", H89*0.93, "Invalid"))) -> 12.873312 | J89: =Table1[[#This Row],[Coating weight (mg)]]/Constants!$C$2 -> 11.955674 | K89: =(Table1[[#This Row],[Coating weight (mg)]]/1000)/(((Table1[[#This Row],[Electrode Thickness(µm)]]-Constants!$E$4)*10^-4)*Constants!$C$4) -> -9.9630615
A90: 11823 | B90: 20_04_04 | C90: FPP-02-Mn-I | D90: RnD | E90: 20.8 | G90: 12.7 | H90: =Table1[[#This Row],[Total electrode weight (mg)]] - IF(ROW()<40, Constants!$B$2 * PI()*(Table1[[#This Row],[Electrode Diameter(mm)]]/(10*2))^2, Constants!$B$4 * PI()*(Table1[[#This Row],[Electrode Diameter(mm)]]/(10*2))^2) -> 16.745073 | I90: =IF(D90="", "", IF(D90="RnD", H90*0.85, IF(D90="Production", H90*0.93, "Invalid"))) -> 14.233312 | J90: =Table1[[#This Row],[Coating weight (mg)]]/Constants!$C$2 -> 13.21873 | K90: =(Table1[[#This Row],[Coating weight (mg)]]/1000)/(((Table1[[#This Row],[Electrode Thickness(µm)]]-Constants!$E$4)*10^-4)*Constants!$C$4) -> -11.015608
A91: 11824 | B91: 51_03_03 | C91: UKP250302 | D91: Production | E91: 24.5 | G91: 12.7 | H91: =Table1[[#This Row],[Total electrode weight (mg)]] - IF(ROW()<40, Constants!$B$2 * PI()*(Table1[[#This Row],[Electrode Diameter(mm)]]/(10*2))^2, Constants!$B$4 * PI()*(Table1[[#This Row],[Electrode Diameter(mm)]]/(10*2))^2) -> 20.445073 | I91: =IF(D91="", "", IF(D91="RnD", H91*0.85, IF(D91="Production", H91*0.93, "Invalid"))) -> 19.013918 | J91: =Table1[[#This Row],[Coating weight (mg)]]/Constants!$C$2 -> 16.139547 | K91: =(Table1[[#This Row],[Coating weight (mg)]]/1000)/(((Table1[[#This Row],[Electrode Thickness(µm)]]-Constants!$E$4)*10^-4)*Constants!$C$4) -> -13.449623
...

Sheet Constants
A1: Substrate | B1: Substarte Aerial density (mg/cm^2) | C1: Substarte/Electrode Area(cm^2) (12.7mm diameter disc) | D1: Substarte/Electrode Area(cm^2) (13mm diameter disc) | E1: Substrate thickness,µm
A2: SAMA 1100 | B2: 4.04 | C2: =PI()*(1.27/2)^2 -> 1.2667687 | D2: =PI()*(1.3/2)^2 -> 1.3273229 | E2: 14
A3: Constantia 1100 - 12 µm' | B3: 3.33 | C3: =PI()*(1.27/2)^2 -> 1.2667687 | D3: =PI()*(1.3/2)^2 -> 1.3273229 | E3: 12
A4: Ding zheng 12 µm | B4: 3.201 | C4: =PI()*(1.27/2)^2 -> 1.2667687 | D4: =PI()*(1.3/2)^2 -> 1.3273229 | E4: 12 | H4: Pi()*(1.27/2)^2
A5: Gränges | B5: 3.301 | C5: =PI()*(1.27/2)^2 -> 1.2667687 | D5: =PI()*(1.3/2)^2 -> 1.3273229

Sheet Production-St.Recipe
A1: Components: | B1: Material | C1: Conc-solid(wt%) | D1: To add(g) | E1: Total_Solid (g) | F1: Component ratio-solid, Slurry/Undried Electrode (wt%) | G1: Component Ratio, dry electrode(Calculated based on 10% crystal water) | H1: Mass(g) | I1: %(w/w)
A2: Cathode active material | B2: Fennac(pure) | C2: 100 | D2: 18 | E2: =D2 -> 18 | F2: 93 | G2: =(0.9*E2)*100/((E2*0.9)+E3+E4+E5) -> 92.282249
A3: Binder | B3: CMC(solution) | C3: 2 | D3: =E3/(C3/100) -> 9.6774194 | E3: =E2*F3/F2 -> 0.19354839 | F3: 1 | G3: =E3*100/(E2*0.9+E3+E4+E5) -> 1.1025358
B4: SBR(solution) | C4: 40 | D4: 0.58 | E4: =E2*F4/F2 -> 0.58064516 | F4: 3 | G4: =E4*100/(E2*0.9+E3+E4+E5) -> 3.3076075
A5: Conductive | B5: C65(pure) | C5: 100 | D5: =E5*1 -> 0.58064516 | E5: =F5*E2/F2 -> 0.58064516 | F5: 3 | G5: =E5*100/(E2*0.9+E3+E4+E5) -> 3.3076075
A6: Solvent | B6: Water - deionised-1st | C6: 0 | D6: =(SUM(E2:E5)-(SUM(D2:D5)*I9/100))/(I9*2/100) -> 4.5562998
B7: Water - deionised-2nd | C7: 0 | D7: =(SUM(E2:E5)-(SUM(D2:D5)*I9/100))/(I9*2/100) -> 4.5562998
A8: Water-total | H8: =(D3-E3)+(D4-E4)+D6+D7 -> 18.595825 | I8: 49
A9: Solid total | H9: =E2*100/F2 -> 19.354839 | I9: 51
E12: Comp | F12: Amount in Kg
E13: Active | F13: 43.2712 | G13: =F13*100/(F13+F14+F15+0.4*F16) -> 93.784415 | H13: =0.9*F13*100/(0.9*F13+F14+F15+0.4*F16) -> 93.141163
E14: C65+VL | F14: 1.8429
E15: CMC | F15: 0.46574944
E16: SBR | F16: 1.3979
